Workbook

Sheet Summary
A1: WIFI&BT Test Summary
A2: Project:
A3: Platform
A4: Chip&Module
A5: OS_Version
A6: Wifi/BT Version | B6: Wifi FW/Driver: BT FW: BT Driver:
A7: FW link
A8: Tester
A9: Category | B9: Test Item | C9: Total case | D9: Pass | E9: Fail | F9: N/A | G9: pass rate | H9: Test result | I9: Comments
A10: Wifi_function | B10: basic function | C10: =Wifi_function!G3 -> 110 | D10: =Wifi_function!H3 -> 0 | E10: =Wifi_function!I3 -> 0 | F10: =Wifi_function!J3 -> 110 | G10: =D10/(C10-F10) -> #DIV/0! | H10: =IF(G10=100%,"Pass",IF(AND(G10>0%,G10<100%),"Fail","")) -> #DIV/0!
A11: Wifi_throughput | B11: peak throughput | C11: ='Wifi_throughput '!N3 -> 40 | D11: ='Wifi_throughput '!O3 -> 20 | E11: ='Wifi_throughput '!P3 -> 0 | F11: ='Wifi_throughput '!Q3 -> 20 | G11: =D11/(C11-F11) -> 1 | H11: =IF(G11=100%,"Pass",IF(AND(G11>0%,G11<100%),"Fail","")) -> Pass
A12: WiFi_compatibility | B12: Different router | C12: =WiFi_compatibility!G3 -> 5 | D12: =WiFi_compatibility!H3 -> 0 | E12: =WiFi_compatibility!I3 -> 0 | F12: =WiFi_compatibility!J3 -> 0 | G12: =D12/(C12-F12) -> 0 | H12: =IF(G12=100%,"Pass",IF(AND(G12>0%,G12<100%),"Fail",""))
A13: RVR&RVO | B13: 2.4G RVR | C13: =COUNTIFS('RVR&RVO'!B:B,B13) -> 4 | D13: =COUNTIFS('RVR&RVO'!$B:$B,$B13,'RVR&RVO'!$H:$H,D$9) -> 0 | E13: =COUNTIFS('RVR&RVO'!$B:$B,$B13,'RVR&RVO'!$H:$H,E$9) -> 0 | F13: =COUNTIFS('RVR&RVO'!$B:$B,$B13,'RVR&RVO'!$H:$H,F$9) -> 0 | G13: =D13/(C13-F13) -> 0 | H13: =IF(G13=100%,"Pass",IF(AND(G13>0%,G13<100%),"Fail",""))
B14: 2.4G RVO | C14: =COUNTIFS('RVR&RVO'!B:B,B14) -> 6 | D14: =COUNTIFS('RVR&RVO'!$B:$B,$B14,'RVR&RVO'!$H:$H,D$9) -> 0 | E14: =COUNTIFS('RVR&RVO'!$B:$B,$B14,'RVR&RVO'!$H:$H,E$9) -> 0 | F14: =COUNTIFS('RVR&RVO'!$B:$B,$B14,'RVR&RVO'!$H:$H,F$9) -> 0 | G14: =D14/(C14-F14) -> 0 | H14: =IF(G14=100%,"Pass",IF(AND(G14>0%,G14<100%),"Fail",""))
B15: 5G RVR | C15: =COUNTIFS('RVR&RVO'!B:B,B15) -> 4 | D15: =COUNTIFS('RVR&RVO'!$B:$B,$B15,'RVR&RVO'!$H:$H,D$9) -> 0 | E15: =COUNTIFS('RVR&RVO'!$B:$B,$B15,'RVR&RVO'!$H:$H,E$9) -> 0 | F15: =COUNTIFS('RVR&RVO'!$B:$B,$B15,'RVR&RVO'!$H:$H,F$9) -> 0 | G15: =D15/(C15-F15) -> 0 | H15: =IF(G15=100%,"Pass",IF(AND(G15>0%,G15<100%),"Fail",""))
B16: 5G RVO | C16: =COUNTIFS('RVR&RVO'!B:B,B16) -> 6 | D16: =COUNTIFS('RVR&RVO'!$B:$B,$B16,'RVR&RVO'!$H:$H,D$9) -> 0 | E16: =COUNTIFS('RVR&RVO'!$B:$B,$B16,'RVR&RVO'!$H:$H,E$9) -> 0 | F16: =COUNTIFS('RVR&RVO'!$B:$B,$B16,'RVR&RVO'!$H:$H,F$9) -> 0 | G16: =D16/(C16-F16) -> 0 | H16: =IF(G16=100%,"Pass",IF(AND(G16>0%,G16<100%),"Fail",""))
A17: BT_function | B17: basic function | C17: =BT_function!G3 -> 70 | D17: =BT_function!H3 -> 0 | E17: =BT_function!I3 -> 0 | F17: =BT_function!J3 -> 70 | G17: =D17/(C17-F17) -> #DIV/0! | H17: =IF(G17=100%,"Pass",IF(AND(G17>0%,G17<100%),"Fail","")) -> #DIV/0!
A18: BT_compatibility | B18: BT Speaker | C18: =COUNTIFS(BT_compatibility!B:B,B18) -> 10 | D18: =COUNTIFS(BT_compatibility!$B:$B,$B18,BT_compatibility!$H:$H,D$9) -> 3 | E18: =COUNTIFS(BT_compatibility!$B:$B,$B18,BT_compatibility!$H:$H,E$9) -> 5 | F18: =COUNTIFS(BT_compatibility!$B:$B,$B18,BT_compatibility!$H:$H,F$9) -> 2 | G18: =D18/(C18-F18) -> 0.375 | H18: =IF(G18=100%,"Pass",IF(AND(G18>0%,G18<100%),"Fail","")) -> Fail
B19: BT Headset | C19: =COUNTIFS(BT_compatibility!B:B,B19) -> 7 | D19: =COUNTIFS(BT_compatibility!$B:$B,$B19,BT_compatibility!$H:$H,D$9) -> 0 | E19: =COUNTIFS(BT_compatibility!$B:$B,$B19,BT_compatibility!$H:$H,E$9) -> 0 | F19: =COUNTIFS(BT_compatibility!$B:$B,$B19,BT_compatibility!$H:$H,F$9) -> 7 | G19: =D19/(C19-F19) -> #DIV/0! | H19: =IF(G19=100%,"Pass",IF(AND(G19>0%,G19<100%),"Fail","")) -> #DIV/0!
B20: BT Remote | C20: =COUNTIFS(BT_compatibility!B:B,B20) -> 4 | D20: =COUNTIFS(BT_compatibility!$B:$B,$B20,BT_compatibility!$H:$H,D$9) -> 0 | E20: =COUNTIFS(BT_compatibility!$B:$B,$B20,BT_compatibility!$H:$H,E$9) -> 0 | F20: =COUNTIFS(BT_compatibility!$B:$B,$B20,BT_compatibility!$H:$H,F$9) -> 4 | G20: =D20/(C20-F20) -> #DIV/0! | H20: =IF(G20=100%,"Pass",IF(AND(G20>0%,G20<100%),"Fail","")) -> #DIV/0!
B21: Keyboard&Mouse | C21: =COUNTIFS(BT_compatibility!B:B,B21) -> 2 | D21: =COUNTIFS(BT_compatibility!$B:$B,$B21,BT_compatibility!$H:$H,D$9) -> 0 | E21: =COUNTIFS(BT_compatibility!$B:$B,$B21,BT_compatibility!$H:$H,E$9) -> 0 | F21: =COUNTIFS(BT_compatibility!$B:$B,$B21,BT_compatibility!$H:$H,F$9) -> 2 | G21: =D21/(C21-F21) -> #DIV/0! | H21: =IF(G21=100%,"Pass",IF(AND(G21>0%,G21<100%),"Fail","")) -> #DIV/0!
B22: BT Handle | C22: =COUNTIFS(BT_compatibility!B:B,B22) -> 2 | D22: =COUNTIFS(BT_compatibility!$B:$B,$B22,BT_compatibility!$H:$H,D$9) -> 0 | E22: =COUNTIFS(BT_compatibility!$B:$B,$B22,BT_compatibility!$H:$H,E$9) -> 0 | F22: =COUNTIFS(BT_compatibility!$B:$B,$B22,BT_compatibility!$H:$H,F$9) -> 2 | G22: =D22/(C22-F22) -> #DIV/0! | H22: =IF(G22=100%,"Pass",IF(AND(G22>0%,G22<100%),"Fail","")) -> #DIV/0!
A23: Stability | B23: WIFI | C23: =COUNTIFS(Stability!B:B,B23) -> 5 | D23: =COUNTIFS(Stability!$B:$B,$B23,Stability!$I:$I,D$9) -> 2 | E23: =COUNTIFS(Stability!$B:$B,$B23,Stability!$I:$I,E$9) -> 1 | F23: =COUNTIFS(Stability!$B:$B,$B23,Stability!$I:$I,F$9) -> 1 | G23: =D23/(C23-F23) -> 0.5 | H23: =IF(G23=100%,"Pass",IF(AND(G23>0%,G23<100%),"Fail","")) -> Fail
B24: BT | C24: =COUNTIFS(Stability!B:B,B24) -> 3 | D24: =COUNTIFS(Stability!$B:$B,$B24,Stability!$I:$I,D$9) -> 0 | E24: =COUNTIFS(Stability!$B:$B,$B24,Stability!$I:$I,E$9) -> 0 | F24: =COUNTIFS(Stability!$B:$B,$B24,Stability!$I:$I,F$9) -> 3 | G24: =D24/(C24-F24) -> #DIV/0! | H24: =IF(G24=100%,"Pass",IF(AND(G24>0%,G24<100%),"Fail","")) -> #DIV/0!
B25: WIFI&BT | C25: =COUNTIFS(Stability!B:B,B25) -> 8 | D25: =COUNTIFS(Stability!$B:$B,$B25,Stability!$I:$I,D$9) -> 0 | E25: =COUNTIFS(Stability!$B:$B,$B25,Stability!$I:$I,E$9) -> 0 | F25: =COUNTIFS(Stability!$B:$B,$B25,Stability!$I:$I,F$9) -> 8 | G25: =D25/(C25-F25) -> #DIV/0! | H25: =IF(G25=100%,"Pass",IF(AND(G25>0%,G25<100%),"Fail","")) -> #DIV/0!
A26: Others Related to WiFi&BT | B26: XTS | C26: For details, please refer to the relevant report
B27: Smoking
B28: YTS
B29: NTS
A30: JIRA ID | B30: Summary | G30: Priority | H30: Owner | I30: Comments
A31: Opening issues
A34: Won`t fix issue
A38: Report Review Owner | B38: 是否可以release | C38: Comments | G38: 签名/日期
A39: QA模块owner签名：
A40: RD模块owner签名：
A41: Release AE owner 签名
A42: Release QA owner 签名

Sheet Wifi_function
A1: WiFi Function Test
A2: Platform_Module | B2: =IF(Summary!B3="","",Summary!B3) | C2: Chip_Module | D2: =IF(Summary!B4="","",Summary!B4) | E2: Tester | F2: =IF(Summary!B8="","",Summary!B8) | G2: Total case | H2: Pass | I2: Fail | J2: N/A
A3: Others | G3: =COUNTIFS(A:A,"*")-4 -> 110 | H3: =COUNTIFS($H4:$H451,H2) -> 0 | I3: =COUNTIFS($H4:$H451,I2) -> 0 | J3: =COUNTIFS($H4:$H451,J2) -> 110
A4: No. | B4: Test_Item | C4: Test_SubItem | D4: Test_Preset | E4: Test_Step | F4: Expected result | G4: Priority | H4: Test_Result | I4: Remark | J4: Author | K4: GM release | L4: Unify release | M4: 是否可自动化 | N4: 不可自动化原因 | O4: Description | P4: API_Summary_JSON
A5: Wifi_Func_001 | B5: WIFI setting | C5: wifi default switch | D5: / | E5: Enter wifi setting | F5: Wifi switch default status is on | G5: P0 | H5: N/A | J5: weidong.feng | K5: Yes | L5: Yes | M5: Yes | O5: Summary（概要） 在WIFI setting场景下执行「wifi default switch」，验证：Wifi switch default status is on Preconditions（前置条件/环境准备） 1. 平台已正常启动并进入系统 2. WiFi 模块已初始化 Steps（操作步骤） Step 1：Enter wifi setting 目的：完成「wifi default switch」测试操作 对应函数：step_open_wifi_settings(...) Checks（检查点） Check 1：Wifi switch default status is on 检查内容：Wifi switch default status is on 对应函数：check_wifi_state(...) | P5: [{"kind": "step", "function_name": "step_open_wifi_settings", "description": "wifi default switch：Enter wifi setting", "category": "wifi", "tags": ["kind:step", "domain:wifi"], "params": {}, "pre_conditions": [], "post_conditions": []}, {"kind": "check", "function_name": "check_wifi_state", "description": "验证wifi default switch：Wifi switch default status is on", "category": "wifi", "tags": ["kind:check", "domain:wifi"], "params": {"expected": {"name": "expected", "type": "bool", "required": true, "default": true, "description": "True=WiFi应开启"}}, "pre_conditions": [{"id": "step_open_wifi_settings", "type": "step", "reason": "需先完成测试步骤"}], "post_conditions": []}]
A6: Wifi_Func_002 | B6: WIFI setting | C6: Turn on/off wifi | D6: / | E6: 1. Turn off wifi 2. Turn on wifi | F6: Wifi can be turn off and cannot research AP After turn on, can display ap list | G6: P0 | H6: N/A | J6: weidong.feng | K6: Yes | L6: Yes | M6: Yes | O6: Summary（概要） 在WIFI setting场景下执行「Turn on/off wifi」，验证：Wifi can be turn off and cannot research AP After Preconditions（前置条件/环境准备） 1. 平台已正常启动并进入系统 2. WiFi 模块已初始化 Steps（操作步骤） Step 1：Turn off wifi 目的：完成「Turn on/off wifi」测试操作 对应函数：step_toggle_wifi(...) Step 2：Turn on wifi 目的：完成「Turn on/off wifi」测试操作 对应函数：step_toggle_wifi(...) Checks（检查点） Check 1：Wifi can be turn off and cannot research AP After turn on, can display ap list 检查内容：Wifi can be turn off and cannot research AP After turn on, can display ap list 对应函数：check_wifi_state(...) | P6: [{"kind": "step", "function_name": "step_toggle_wifi", "description": "Turn on/off wifi：Turn off wifi", "category": "wifi", "tags": ["kind:step", "domain:wifi"], "params": {"enabled": {"name": "enabled", "type": "bool", "required": true, "default": false, "description": "False=关闭WiFi"}}, "pre_conditions": [], "post_conditions": []}, {"kind": "check", "function_name": "check_wifi_state", "description": "验证Turn on/off wifi：Wifi can be turn off and cannot research AP After turn on, c", "category": "wifi", "tags": ["kind:check", "domain:wifi"], "params": {"expected": {"name": "expected", "type": "bool", "required": true, "default": true, "description": "True=WiFi应开启"}}, "pre_conditions": [{"id": "step_toggle_wifi", "type": "step", "reason": "需先完成测试步骤"}], "post_conditions": []}]
A7: Wifi_Func_003 | B7: WIFI setting | C7: Wifi list interface | D7: Connecting wifi | E7: set ap ssid to 32-bit, and then open and check Wifi list interface | F7: 1.Wifi is sorted by strong to weak signal 2.The encryption mode of the current AP is identified in the help text of the AP 3.Verify that the 32-bit SSID is displayed intact | G7: P1 | H7: N/A | J7: weidong.feng | M7: Yes | O7: Summary（概要） 在WIFI setting场景下执行「Wifi list interface」，验证：Wifi is sorted by strong to weak signal；The encryption mode of the current AP Preconditions（前置条件/环境准备） 1. 平台已正常启动并进入系统 2. WiFi 模块已初始化 3. Connecting wifi Steps（操作步骤） Step 1：set ap ssid to 32-bit, and then open and check Wifi list interface 目的：完成「Wifi list interface」测试操作 对应函数：step_open_wifi_settings(...) Checks（检查点） Check 1：Wifi is sorted by strong to weak signal 检查内容：Wifi is sorted by strong to weak signal 对应函数：check_wifi_state(...) Check 2：The encryption mode of the current AP is identified in the help text of the AP 检查内容：The encryption mode of the current AP is identified in the help text of the AP 对应函数：check_the_encryption_mode_of_the_c(...) Check 3：Verify that the 32-bit SSID is displayed intact 检查内容：Verify that the 32-bit SSID is displayed intact 对应函数：check_ap_list_display(...) | P7: [{"kind": "step", "function_name": "step_open_wifi_settings", "description": "Wifi list interface：set ap ssid to 32-bit, and then open and check Wifi list int", "category": "wifi", "tags": ["kind:step", "domain:wifi"], "params": {}, "pre_conditions": [], "post_conditions": []}, {"kind": "check", "function_name": "check_wifi_state", "description": "验证Wifi list interface：Wifi is sorted by strong to weak signal", "category": "wifi", "tags": ["kind:check", "domain:wifi"], "params": {"expected": {"name": "expected", "type": "bool", "required": true, "default": true, "description": "True=WiFi应开启"}}, "pre_conditions": [{"id": "step_open_wifi_settings", "type": "step", "reason": "需先完成测试步骤"}], "post_conditions": []}, {"kind": "check", "function_name": "check_the_encryption_mode_of_the_c", "description": "验证Wifi list interface：The encryption mode of the current AP is identified in the h", "category": "wifi", "tags": ["kind:check", "domain:wifi"], "params": {}, "pre_conditions": [{"id": "step_open_wifi_settings", "type": "step", "reason": "需先完成测试步骤"}], "post_conditions": []}, {"kind": "check", "function_name": "check_ap_list_display", "description": "验证Wifi list interface：Verify that the 32-bit SSID is displayed intact", "category": "wifi", "tags": ["kind:check", "domain:wifi"], "params": {}, "pre_conditions": [{"id": "step_open_wifi_settings", "type": "step", "reason": "需先完成测试步骤"}], "post_conditions": []}]
A8: Wifi_Func_004 | B8: WIFI setting | C8: connect successful | D8: Multiple APs | E8: Select an AP to connect input the rignt password | F8: prompt the connection is successful, and the connected AP display is ranked first and shows the connected status. | G8: P1 | H8: N/A | J8: weidong.feng | K8: Yes | L8: Yes | M8: Yes | O8: Summary（概要） 在WIFI setting场景下执行「connect successful」，验证：prompt the connection is successful, and the conn Preconditions（前置条件/环境准备） 1. 平台已正常启动并进入系统 2. WiFi 模块已初始化 3. Multiple APs Steps（操作步骤） Step 1：Select an AP to connect input the rignt password 目的：完成「connect successful」测试操作 对应函数：step_connect_wifi(...) Checks（检查点） Check 1：prompt the connection is successful, and the connected AP display is ranked fir 检查内容：prompt the connection is successful, and the connected AP display is ranked first and shows the connected status. 对应函数：check_wifi_connected(...) | P8: [{"kind": "step", "function_name": "step_connect_wifi", "description": "connect successful：Select an AP to connect input the rignt password", "category": "wifi", "tags": ["kind:step", "domain:wifi"], "params": {"ssid": {"name": "ssid", "type": "str", "required": true, "default": null, "description": "目标AP的SSID"}, "password": {"name": "password", "type": "str", "required": false, "default": null, "description": "WiFi密码，开放网络可为空"}, "auth_type": {"name": "auth_type", "type": "str", "required": false, "default": null, "description": "认证类型如 WPA2/WPA3/Open/WEP"}}, "pre_conditions": [], "post_conditions": []}, {"kind": "check", "function_name": "check_wifi_connected", "description": "验证connect successful：prompt the connection is successful, and the connected AP d", "category": "wifi", "tags": ["kind:check", "domain:wifi"], "params": {"expected_ssid": {"name": "expected_ssid", "type": "str", "required": false, "default": null, "description": "预期已连接的SSID"}}, "pre_conditions": [{"id": "step_connect_wifi", "type": "step", "reason": "需先完成测试步骤"}], "post_conditions": []}]
A9: Wifi_Func_005 | B9: WIFI setting | C9: connect fail | D9: Multiple APs | E9: Select an AP to connect input the wrong password | F9: prompt some info, such as: the connection fails and you need to try to connect again | G9: P1 | H9: N/A | J9: weidong.feng | M9: Yes | O9: Summary（概要） 在WIFI setting场景下执行「connect fail」，验证：prompt some info, such as: the connection fails an Preconditions（前置条件/环境准备） 1. 平台已正常启动并进入系统 2. WiFi 模块已初始化 3. Multiple APs Steps（操作步骤） Step 1：Select an AP to connect input the wrong password 目的：完成「connect fail」测试操作 对应函数：step_connect_wifi(...) Checks（检查点） Check 1：prompt some info, such as: the connection fails and you need to try to connect a 检查内容：prompt some info, such as: the connection fails and you need to try to connect again 对应函数：check_wifi_connection_failed(...) | P9: [{"kind": "step", "function_name": "step_connect_wifi", "description": "connect fail：Select an AP to connect input the wrong password", "category": "wifi", "tags": ["kind:step", "domain:wifi"], "params": {"ssid": {"name": "ssid", "type": "str", "required": true, "default": null, "description": "目标AP的SSID"}, "password": {"name": "password", "type": "str", "required": false, "default": null, "description": "WiFi密码，开放网络可为空"}, "auth_type": {"name": "auth_type", "type": "str", "required": false, "default": null, "description": "认证类型如 WPA2/WPA3/Open/WEP"}}, "pre_conditions": [], "post_conditions": []}, {"kind": "check", "function_name": "check_wifi_connection_failed", "description": "验证connect fail：prompt some info, such as: the connection fails and you need", "category": "wifi", "tags": ["kind:check", "domain:wifi"], "params": {}, "pre_conditions": [{"id": "step_connect_wifi", "type": "step", "reason": "需先完成测试步骤"}], "post_conditions": []}]
A10: Wifi_Func_006 | B10: WIFI setting | C10: Wifi connecting interface | D10: Connecting wifi | E10: open and check Wifi connecting interface | F10: 1.Display the SSID of the current AP 2.Hide password optionswas clicked by default | G10: P1 | H10: N/A | J10: weidong.feng | M10: Yes | N10: Connecting 窗口需要人为选择并判断是否符合预期 | O10: Summary（概要） 在WIFI setting场景下执行「Wifi connecting interface」，验证：Display the SSID of the current AP；Hide password optionswas clicked by Preconditions（前置条件/环境准备） 1. 平台已正常启动并进入系统 2. WiFi 模块已初始化 3. Connecting wifi Steps（操作步骤） Step 1：open and check Wifi connecting interface 目的：完成「Wifi connecting interface」测试操作 对应函数：step_toggle_wifi(...) Checks（检查点） Check 1：Display the SSID of the current AP 检查内容：Display the SSID of the current AP 对应函数：check_ap_list_display(...) Check 2：Hide password optionswas clicked by default 检查内容：Hide password optionswas clicked by default 对应函数：check_hide_password_optionswas_cli(...) | P10: [{"kind": "step", "function_name": "step_toggle_wifi", "description": "Wifi connecting interface：open and check Wifi connecting interface", "category": "wifi", "tags": ["kind:step", "domain:wifi"], "params": {"enabled": {"name": "enabled", "type": "bool", "required": true, "default": true, "description": "True=开启WiFi"}}, "pre_conditions": [], "post_conditions": []}, {"kind": "check", "function_name": "check_ap_list_display", "description": "验证Wifi connecting interface：Display the SSID of the current AP", "category": "wifi", "tags": ["kind:check", "domain:wifi"], "params": {}, "pre_conditions": [{"id": "step_toggle_wifi", "type": "step", "reason": "需先完成测试步骤"}], "post_conditions": []}, {"kind": "check", "function_name": "check_hide_password_optionswas_cli", "description": "验证Wifi connecting interface：Hide password optionswas clicked by default", "category": "wifi", "tags": ["kind:check", "domain:wifi"], "params": {}, "pre_conditions": [{"id": "step_toggle_wifi", "type": "step", "reason": "需先完成测试步骤"}], "post_conditions": []}]
A11: Wifi_Func_007 | B11: WIFI setting | C11: WiFi/Ethernet switching | E11: Plug and unplug the network cable after the platform is connected to the AP. | F11: After the platform is plugged into the network cable, the WiFi is disconnected and connected to the Ethernet; after the network cable is unplugged, the WiFi is automatically reconnected; priority: Ethernet>WiFi | G11: P1 | H11: N/A | J11: weidong.feng | M11: Yes | O11: Summary（概要） 在WIFI setting场景下执行「WiFi/Ethernet switching」，验证：After the platform is plugged into the network cab Preconditions（前置条件/环境准备） 1. 平台已正常启动并进入系统 2. WiFi 模块已初始化 Steps（操作步骤） Step 1：Plug and unplug the network cable after the platform is connected to the AP. 目的：完成「WiFi/Ethernet switching」测试操作 对应函数：step_connect_wifi(...) Checks（检查点） Check 1：After the platform is plugged into the network cable, the WiFi is disconnected a 检查内容：After the platform is plugged into the network cable, the WiFi is disconnected and connected to the Ethernet; after the network cable is unplugged, the WiFi is automatically reconnected; priority: Ethernet>WiFi 对应函数：check_wifi_disconnected(...) | P11: [{"kind": "step", "function_name": "step_connect_wifi", "description": "WiFi/Ethernet switching：Plug and unplug the network cable after the platform is conn", "category": "wifi", "tags": ["kind:step", "domain:wifi"], "params": {"ssid": {"name": "ssid", "type": "str", "required": true, "default": null, "description": "目标AP的SSID"}, "password": {"name": "password", "type": "str", "required": false, "default": null, "description": "WiFi密码，开放网络可为空"}, "auth_type": {"name": "auth_type", "type": "str", "required": false, "default": null, "description": "认证类型如 WPA2/WPA3/Open/WEP"}}, "pre_conditions": [], "post_conditions": []}, {"kind": "check", "function_name": "check_wifi_disconnected", "description": "验证WiFi/Ethernet switching：After the platform is plugged into the network cable, the Wi", "category": "wifi", "tags": ["kind:check", "domain:wifi"], "params": {}, "pre_conditions": [{"id": "step_connect_wifi", "type": "step", "reason": "需先完成测试步骤"}], "post_conditions": []}]
A12: Wifi_Func_008 | B12: WIFI setting | C12: forget password | E12: Select one connected ap, to click "Do not save" or "Forget network" option | F12: The platform will automatically delete the saved wifi password | G12: P1 | H12: N/A | J12: weidong.feng | K12: Yes | L12: Yes | M12: Yes | O12: Summary（概要） 在WIFI setting场景下执行「forget password」，验证：The platform will automatically delete the saved w Preconditions（前置条件/环境准备） 1. 平台已正常启动并进入系统 2. WiFi 模块已初始化 Steps（操作步骤） Step 1：Select one connected ap, to click "Do not save" or "Forget network" option 目的：完成「forget password」测试操作 对应函数：step_connect_wifi(...) Checks（检查点） Check 1：The platform will automatically delete the saved wifi password 检查内容：The platform will automatically delete the saved wifi password 对应函数：check_wifi_password_forgotten(...) | P12: [{"kind": "step", "function_name": "step_connect_wifi", "description": "forget password：Select one connected ap, to click \"Do not save\" or \"Forget n", "category": "wifi", "tags": ["kind:step", "domain:wifi"], "params": {"ssid": {"name": "ssid", "type": "str", "required": true, "default": null, "description": "目标AP的SSID"}, "password": {"name": "password", "type": "str", "required": false, "default": null, "description": "WiFi密码，开放网络可为空"}, "auth_type": {"name": "auth_type", "type": "str", "required": false, "default": null, "description": "认证类型如 WPA2/WPA3/Open/WEP"}}, "pre_conditions": [], "post_conditions": []}, {"kind": "check", "function_name": "check_wifi_password_forgotten", "description": "验证forget password：The platform will automatically delete the saved wifi passwo", "category": "wifi", "tags": ["kind:check", "domain:wifi"], "params": {"ssid": {"name": "ssid", "type": "str", "required": true, "default": null, "description": "已忘记密码的SSID"}}, "pre_conditions": [{"id": "step_connect_wifi", "type": "step", "reason": "需先完成测试步骤"}], "post_conditions": []}]
A13: Wifi_Func_009 | B13: WIFI setting | C13: set static ip | E13: Use static IP | F13: Static IP can set successful | G13: P1 | H13: N/A | J13: weidong.feng | M13: Yes | O13: Summary（概要） 在WIFI setting场景下执行「set static ip」，验证：Static IP can set successful Preconditions（前置条件/环境准备） 1. 平台已正常启动并进入系统 2. WiFi 模块已初始化 Steps（操作步骤） Step 1：Use static IP 目的：完成「set static ip」测试操作 对应函数：step_set_wifi_static_ip(...) Checks（检查点） Check 1：Static IP can set successful 检查内容：Static IP can set successful 对应函数：check_wifi_ip_mode(...) | P13: [{"kind": "step", "function_name": "step_set_wifi_static_ip", "description": "set static ip：Use static IP", "category": "wifi", "tags": ["kind:step", "domain:wifi"], "params": {"ip": {"name": "ip", "type": "str", "required": true, "default": null, "description": "静态IP地址"}, "subnet": {"name": "subnet", "type": "str", "required": false, "default": null, "description": "子网掩码"}, "gateway": {"name": "gateway", "type": "str", "required": false, "default": null, "description": "网关地址"}}, "pre_conditions": [], "post_conditions": []}, {"kind": "check", "function_name": "check_wifi_ip_mode", "description": "验证set static ip：Static IP can set successful", "category": "wifi", "tags": ["kind:check", "domain:wifi"], "params": {"expected_mode": {"name": "expected_mode", "type": "str", "required": true, "default": "static", "description": "预期IP模式"}}, "pre_conditions": [{"id": "step_set_wifi_static_ip", "type": "step", "reason": "需先完成测试步骤"}], "post_conditions": []}]
A14: Wifi_Func_010 | B14: WIFI setting | C14: network working | E14: Access to the network | F14: The platform should be able to access web news or videos normally | G14: P1 | H14: N/A | J14: weidong.feng | K14: Yes | L14: Yes | M14: Yes | O14: Summary（概要） 在WIFI setting场景下执行「network working」，验证：The platform should be able to access web news or Preconditions（前置条件/环境准备） 1. 平台已正常启动并进入系统 2. WiFi 模块已初始化 Steps（操作步骤） Step 1：Access to the network 目的：完成「network working」测试操作 对应函数：step_access_network_or_play_video(...) Checks（检查点） Check 1：The platform should be able to access web news or videos normally 检查内容：The platform should be able to access web news or videos normally 对应函数：check_network_accessible(...) | P14: [{"kind": "step", "function_name": "step_access_network_or_play_video", "description": "network working：Access to the network", "category": "wifi", "tags": ["kind:step", "domain:wifi"], "params": {"target": {"name": "target", "type": "str", "required": false, "default": null, "description": "访问目标或视频平台名称"}}, "pre_conditions": [], "post_conditions": []}, {"kind": "check", "function_name": "check_network_accessible", "description": "验证network working：The platform should be able to access web news or videos nor", "category": "wifi", "tags": ["kind:check", "domain:wifi"], "params": {}, "pre_conditions": [{"id": "step_access_network_or_play_video", "type": "step", "reason": "需先完成测试步骤"}], "post_conditions": []}]
A15: Wifi_Func_011 | B15: WIFI setting | C15: Flight mode | E15: turning on Flight mode | F15: 1.Wifi automatically turns off when airplane mode is turned on 2.After turning on the flight mode, you can manually turn on the wifi and continue to access the Internet. | G15: P1 | H15: N/A | J15: weidong.feng | M15: Yes | O15: Summary（概要） 在WIFI setting场景下执行「Flight mode」，验证：Wifi automatically turns off when airplane mode is；After turning on the flight mode, Preconditions（前置条件/环境准备） 1. 平台已正常启动并进入系统 2. WiFi 模块已初始化 Steps（操作步骤） Step 1：turning on Flight mode 目的：完成「Flight mode」测试操作 对应函数：step_set_flight_mode(...) Checks（检查点） Check 1：Wifi automatically turns off when airplane mode is turned on 检查内容：Wifi automatically turns off when airplane mode is turned on 对应函数：check_wifi_state(...) Check 2：After turning on the flight mode, you can manually turn on the wifi and continue 检查内容：After turning on the flight mode, you can manually turn on the wifi and continue to access the Internet. 对应函数：check_wifi_state(...) | P15: [{"kind": "step", "function_name": "step_set_flight_mode", "description": "Flight mode：turning on Flight mode", "category": "wifi", "tags": ["kind:step", "domain:wifi"], "params": {"enabled": {"name": "enabled", "type": "bool", "required": true, "default": true, "description": "True=开启飞行模式"}}, "pre_conditions": [], "post_conditions": []}, {"kind": "check", "function_name": "check_wifi_state", "description": "验证Flight mode：Wifi automatically turns off when airplane mode is turned on", "category": "wifi", "tags": ["kind:check", "domain:wifi"], "params": {"expected": {"name": "expected", "type": "bool", "required": true, "default": true, "description": "True=WiFi应开启"}}, "pre_conditions": [{"id": "step_set_flight_mode", "type": "step", "reason": "需先完成测试步骤"}], "post_conditions": []}]
A16: Wifi_Func_012 | B16: WIFI setting | C16: Password keyboard input interface | D16: Multiple APs | E16: 1. open and check password keyboard input interface 2.when number of input passwords is less than the standard number of passwords 3.When the number of digits entered is equal to or more than the standard number of digits 4. When entering a password, if Show Password is set to Hide password 5. Click the cancel button or press the back button | F16: 1.Can pop up the default keyboard input 2.the connection button is grayed out or the click connection has no effect 3. the connection button can be connected 4. the passwords are all displayed in "..." m; or the entered passwords are all displayed 5. return to the AP list interface | G16: P1 | H16: N/A | J16: weidong.feng | M16: No | N16: 键盘行为需要人为判断是否符合预期 | O16: Summary（概要） 在WIFI setting场景下执行「Password keyboard input interface」，验证：Can pop up the default keyboard input；the connection button is Preconditions（前置条件/环境准备） 1. 平台已正常启动并进入系统 2. WiFi 模块已初始化 3. Multiple APs Steps（操作步骤） Step 1：open and check password keyboard input interface 目的：完成「Password keyboard input interface」测试操作 对应函数：step_open_and_check_password_keyb(...) Step 2：when number of input passwords is less than the standard number of passwords 目的：完成「Password keyboard input interface」测试操作 对应函数：step_connect_wifi(...) Step 3：When the number of digits entered is equal to or more than the standard number of digits 目的：完成「Password keyboard input interface」测试操作 对应函数：step_when_the_number_of_digits_en(...) Step 4：When entering a password, if Show Password is set to Hide password 目的：完成「Password keyboard input interface」测试操作 对应函数：step_connect_wifi(...) Step 5：Click the cancel button or press the back button 目的：完成「Password keyboard input interface」测试操作 对应函数：step_click_the_cancel_button_or_p(...) Checks（检查点） Check 1：Can pop up the default keyboard input 检查内容：Can pop up the default keyboard input 对应函数：check_can_pop_up_the_default_keybo(...) Check 2：the connection button is grayed out or the click connection has no effect 检查内容：the connection button is grayed out or the click connection has no effect 对应函数：check_the_connection_button_is_gra(...) Check 3：the connection button can be connected 检查内容：the connection button can be connected 对应函数：check_the_connection_button_can_be(...) Check 4：the passwords are all displayed in "..." m; or the entered passwords are all dis 检查内容：the passwords are all displayed in "..." m; or the entered passwords are all displayed 对应函数：check_wifi_password_input_ui(...) Check 5：return to the AP list interface 检查内容：return to the AP list interface 对应函数：check_ap_list_display(...) | P16: [{"kind": "step", "function_name": "step_open_and_check_password_keyb", "description": "Password keyboard input interface：open and check password keyboard input interface", "category": "wifi", "tags": ["kind:step", "domain:wifi"], "params": {}, "pre_conditions": [], "post_conditions": []}, {"kind": "step", "function_name": "step_connect_wifi", "description": "Password keyboard input interface：when number of input passwords is less than the standard num", "category": "wifi", "tags": ["kind:step", "domain:wifi"], "params": {"ssid": {"name": "ssid", "type": "str", "required": true, "default": null, "description": "目标AP的SSID"}, "password": {"name": "password", "type": "str", "required": false, "default": null, "description": "WiFi密码，开放网络可为空"}, "auth_type": {"name": "auth_type", "type": "str", "required": false, "default": null, "description": "认证类型如 WPA2/WPA3/Open/WEP"}}, "pre_conditions": [{"id": "step_open_and_check_password_keyb", "type": "step", "reason": "前置步骤必须先完成"}], "post_conditions": []}, {"kind": "step", "function_name": "step_when_the_number_of_digits_en", "description": "Password keyboard input interface：When the number of digits entered is equal to or more than t", "category": "wifi", "tags": ["kind:step", "domain:wifi"], "params": {}, "pre_conditions": [{"id": "step_connect_wifi", "type": "step", "reason": "前置步骤必须先完成"}], "post_conditions": []}, {"kind": "step", "function_name": "step_click_the_cancel_button_or_p", "description": "Password keyboard input interface：Click the cancel button or press the back button", "category": "wifi", "tags": ["kind:step", "domain:wifi"], "params": {}, "pre_conditions": [{"id": "step_connect_wifi", "type": "step", "reason": "前置步骤必须先完成"}], "post_conditions": []}, {"kind": "check", "function_name": "check_can_pop_up_the_default_keybo", "description": "验证Password keyboard input interface：Can pop up the default keyboard input", "category": "wifi", "tags": ["kind:check", "domain:wifi"], "params": {}, "pre_conditions": [{"id": "step_click_the_cancel_button_or_p", "type": "step", "reason": "需先完成测试步骤"}], "post_conditions": []}, {"kind": "check", "function_name": "check_the_connection_button_is_gra", "description": "验证Password keyboard input interface：the connection button is grayed out or the click connection ", "category": "wifi", "tags": ["kind:check", "domain:wifi"], "params": {}, "pre_conditions": [{"id": "step_click_the_cancel_button_or_p", "type": "step", "reason": "需先完成测试步骤"}], "post_conditions": []}, {"kind": "check", "function_name": "check_the_connection_button_can_be", "description": "验证Password keyboard input interface：the connection button can be connected", "category": "wifi", "tags": ["kind:check", "domain:wifi"], "params": {}, "pre_conditions": [{"id": "step_click_the_cancel_button_or_p", "type": "step", "reason": "需先完成测试步骤"}], "post_conditions": []}, {"kind": "check", "function_name": "check_wifi_password_input_ui", "description": "验证Password keyboard input interface：the passwords are all displayed in \"...\" m; or the entered p", "category": "wifi", "tags": ["kind:check", "domain:wifi"], "params": {}, "pre_conditions": [{"id": "step_click_the_cancel_button_or_p", "type": "step", "reason": "需先完成测试步骤"}], "post_conditions": []}, {"kind": "check", "function_name": "check_ap_list_display", "description": "验证Password keyboard input interface：return to the AP list interface", "category": "wifi", "tags": ["kind:check", "domain:wifi"], "params": {}, "pre_conditions": [{"id": "step_click_the_cancel_button_or_p", "type": "step", "reason": "需先完成测试步骤"}], "post_conditions": []}]
A17: Wifi_Func_013 | B17: WIFI setting | C17: quick connect | E17: 1.DUT enter settings-Network&Internet-Quick connect 2.Android 12 mobile phone connect with an VPN AP (which is 1/6/11/36/64/149/165channel)and enter AP detail interface 3.Add device and then scan the QR code | F17: 1.DUT will auto connect with the AP which same as mobile phone connected and phone prompt AP connect success | G17: P1 | H17: N/A | J17: weidong.feng | K17: Yes | L17: Yes | M17: No | N17: 如何自动化控制 mobile 设备 | O17: Summary（概要） 在WIFI setting场景下执行「quick connect」，验证：DUT will auto connect with the AP which same as m Preconditions（前置条件/环境准备） 1. 平台已正常启动并进入系统 2. WiFi 模块已初始化 Steps（操作步骤） Step 1：DUT enter settings-Network&Internet-Quick connect 目的：完成「quick connect」测试操作 对应函数：step_quick_connect_wifi(...) Step 2：Android 12 mobile phone connect with an VPN AP (which is 1/6/11/36/64/149/165channel)and enter AP detail interface 目的：完成「quick connect」测试操作 对应函数：step_connect_wifi(...) Step 3：Add device and then scan the QR code 目的：完成「quick connect」测试操作 对应函数：step_quick_connect_wifi(...) Checks（检查点） Check 1：DUT will auto connect with the AP which same as mobile phone connected and phon 检查内容：DUT will auto connect with the AP which same as mobile phone connected and phone prompt AP connect success 对应函数：check_wifi_connected(...) | P17: [{"kind": "step", "function_name": "step_quick_connect_wifi", "description": "quick connect：DUT enter settings-Network&Internet-Quick connect", "category": "wifi", "tags": ["kind:step", "domain:wifi"], "params": {}, "pre_conditions": [], "post_conditions": []}, {"kind": "step", "function_name": "step_connect_wifi", "description": "quick connect：Android 12 mobile phone connect with an VPN AP (which is 1/6", "category": "wifi", "tags": ["kind:step", "domain:wifi"], "params": {"ssid": {"name": "ssid", "type": "str", "required": true, "default": null, "description": "目标AP的SSID"}, "password": {"name": "password", "type": "str", "required": false, "default": null, "description": "WiFi密码，开放网络可为空"}, "auth_type": {"name": "auth_type", "type": "str", "required": false, "default": null, "description": "认证类型如 WPA2/WPA3/Open/WEP"}}, "pre_conditions": [{"id": "step_quick_connect_wifi", "type": "step", "reason": "前置步骤必须先完成"}], "post_conditions": []}, {"kind": "check", "function_name": "check_wifi_connected", "description": "验证quick connect：DUT will auto connect with the AP which same as mobile phon", "category": "wifi", "tags": ["kind:check", "domain:wifi"], "params": {"expected_ssid": {"name": "expected_ssid", "type": "str", "required": false, "default": null, "description": "预期已连接的SSID"}}, "pre_conditions": [{"id": "step_quick_connect_wifi", "type": "step", "reason": "需先完成测试步骤"}], "post_conditions": []}]
A18: Wifi_Func_014 | B18: WIFI setting | C18: country code | E18: 1. input cmd to check countrycode getprop ro.boot.wificountrycode 2. change another country in Startup wizard | F18: countrycode follow with setup country such as: US | G18: P1 | H18: N/A | M18: Yes | O18: Summary（概要） 在WIFI setting场景下执行「country code」，验证：countrycode follow with setup country such as: US Preconditions（前置条件/环境准备） 1. 平台已正常启动并进入系统 2. WiFi 模块已初始化 Steps（操作步骤） Step 1：input cmd to check countrycode getprop ro.boot.wificountrycode 目的：完成「country code」测试操作 对应函数：step_set_country_code(...) Step 2：change another country in Startup wizard 目的：完成「country code」测试操作 对应函数：step_set_country_code(...) Checks（检查点） Check 1：countrycode follow with setup country such as: US 检查内容：countrycode follow with setup country such as: US 对应函数：check_country_code(...) | P18: [{"kind": "step", "function_name": "step_set_country_code", "description": "country code：input cmd to check countrycode getprop ro.boot.wificountryco", "category": "wifi", "tags": ["kind:step", "domain:wifi"], "params": {"country": {"name": "country", "type": "str", "required": true, "default": null, "description": "国家代码如 US/CN"}}, "pre_conditions": [], "post_conditions": []}, {"kind": "check", "function_name": "check_country_code", "description": "验证country code：countrycode follow with setup country such as: US", "category": "wifi", "tags": ["kind:check", "domain:wifi"], "params": {"expected_code": {"name": "expected_code", "type": "str", "required": true, "default": null, "description": "预期国家代码如 US/CN"}}, "pre_conditions": [{"id": "step_set_country_code", "type": "step", "reason": "需先完成测试步骤"}], "post_conditions": []}]
A19: Wifi_Func_026 | B19: Connect AP | C19: Hide SSID | E19: hide ap on router settings | F19: 1.Platform cannot search the AP 2.The platform enters the SSID and password may successfully connect to the AP. | G19: P1 | H19: N/A | J19: weidong.feng | K19: Yes | L19: Yes | M19: Todo | N19: 该项标记为 TODO，提示以下 AP Case 均需要提供满足条件的路由器设备来完成 Case 开发，同时测试端需搭建 AUT 环境，实现路由器自动化控制 1.模拟实现 2.是否能覆盖 3.煲机类 | O19: Summary（概要） 在Connect AP场景下执行「Hide SSID」，验证：Platform cannot search the AP；The platform enters the SSID and password may succ Preconditions（前置条件/环境准备） 1. 平台已正常启动并进入系统 2. WiFi 模块已初始化 Steps（操作步骤） Step 1：hide ap on router settings 目的：完成「Hide SSID」测试操作 对应函数：step_configure_ap_hide_ssid(...) Checks（检查点） Check 1：Platform cannot search the AP 检查内容：Platform cannot search the AP 对应函数：check_ap_not_visible(...) Check 2：The platform enters the SSID and password may successfully connect to the AP. 检查内容：The platform enters the SSID and password may successfully connect to the AP. 对应函数：check_the_platform_enters_the_ssid(...) | P19: [{"kind": "step", "function_name": "step_configure_ap_hide_ssid", "description": "Hide SSID：hide ap on router settings", "category": "wifi", "tags": ["kind:step", "domain:wifi"], "params": {"hidden": {"name": "hidden", "type": "bool", "required": true, "default": true, "description": "True=隐藏SSID"}}, "pre_conditions": [], "post_conditions": []}, {"kind": "check", "function_name": "check_ap_not_visible", "description": "验证Hide SSID：Platform cannot search the AP", "category": "wifi", "tags": ["kind:check", "domain:wifi"], "params": {}, "pre_conditions": [{"id": "step_configure_ap_hide_ssid", "type": "step", "reason": "需先完成测试步骤"}], "post_conditions": []}, {"kind": "check", "function_name": "check_the_platform_enters_the_ssid", "description": "验证Hide SSID：The platform enters the SSID and password may successfully c", "category": "wifi", "tags": ["kind:check", "domain:wifi"], "params": {}, "pre_conditions": [{"id": "step_configure_ap_hide_ssid", "type": "step", "reason": "需先完成测试步骤"}], "post_conditions": []}]
A20: Wifi_Func_027 | B20: Connect AP | C20: Unhide SSID | E20: unhide ap on router settings | F20: Platform can search the AP and connect it | G20: P1 | H20: N/A | J20: weidong.feng | M20: Yes | O20: Summary（概要） 在Connect AP场景下执行「Unhide SSID」，验证：Platform can search the AP and connect it Preconditions（前置条件/环境准备） 1. 平台已正常启动并进入系统 2. WiFi 模块已初始化 Steps（操作步骤） Step 1：unhide ap on router settings 目的：完成「Unhide SSID」测试操作 对应函数：step_configure_ap_hide_ssid(...) Checks（检查点） Check 1：Platform can search the AP and connect it 检查内容：Platform can search the AP and connect it 对应函数：check_wifi_connected(...) | P20: [{"kind": "step", "function_name": "step_configure_ap_hide_ssid", "description": "Unhide SSID：unhide ap on router settings", "category": "wifi", "tags": ["kind:step", "domain:wifi"], "params": {"hidden": {"name": "hidden", "type": "bool", "required": true, "default": true, "description": "True=隐藏SSID"}}, "pre_conditions": [], "post_conditions": []}, {"kind": "check", "function_name": "check_wifi_connected", "description": "验证Unhide SSID：Platform can search the AP and connect it", "category": "wifi", "tags": ["kind:check", "domain:wifi"], "params": {"expected_ssid": {"name": "expected_ssid", "type": "str", "required": false, "default": null, "description": "预期已连接的SSID"}}, "pre_conditions": [{"id": "step_configure_ap_hide_ssid", "type": "step", "reason": "需先完成测试步骤"}], "post_conditions": []}]
A21: Wifi_Func_015 | B21: Connect AP | C21: The connected AP is powered off/on | E21: 1.Connect an AP 2.The AP power off 3.The AP power on | F21: 1.After step 2，platform disconnect with the AP 2.After step 3，platform auto connect with the AP | G21: P1 | H21: N/A | J21: weidong.feng | M21: Yes | O21: Summary（概要） 在Connect AP场景下执行「The connected AP is powered off/on」，验证：After step 2，platform disconnect with the AP；After step 3，platfo Preconditions（前置条件/环境准备） 1. 平台已正常启动并进入系统 2. WiFi 模块已初始化 Steps（操作步骤） Step 1：Connect an AP 目的：完成「The connected AP is powered off/on」测试操作 对应函数：step_connect_wifi(...) Step 2：The AP power off 目的：完成「The connected AP is powered off/on」测试操作 对应函数：step_power_off_ap(...) Step 3：The AP power on 目的：完成「The connected AP is powered off/on」测试操作 对应函数：step_power_on_ap(...) Checks（检查点） Check 1：After step 2，platform disconnect with the AP 检查内容：After step 2，platform disconnect with the AP 对应函数：check_wifi_disconnected(...) Check 2：After step 3，platform auto connect with the AP 检查内容：After step 3，platform auto connect with the AP 对应函数：check_wifi_auto_reconnected(...) | P21: [{"kind": "step", "function_name": "step_connect_wifi", "description": "The connected AP is powered off/on：Connect an AP", "category": "wifi", "tags": ["kind:step", "domain:wifi"], "params": {"ssid": {"name": "ssid", "type": "str", "required": true, "default": null, "description": "目标AP的SSID"}, "password": {"name": "password", "type": "str", "required": false, "default": null, "description": "WiFi密码，开放网络可为空"}, "auth_type": {"name": "auth_type", "type": "str", "required": false, "default": null, "description": "认证类型如 WPA2/WPA3/Open/WEP"}}, "pre_conditions": [], "post_conditions": []}, {"kind": "step", "function_name": "step_power_off_ap", "description": "The connected AP is powered off/on：The AP power off", "category": "wifi", "tags": ["kind:step", "domain:wifi"], "params": {"ap_id": {"name": "ap_id", "type": "str", "required": false, "default": "AP1", "description": "AP标识"}}, "pre_conditions": [{"id": "step_connect_wifi", "type": "step", "reason": "前置步骤必须先完成"}], "post_conditions": []}, {"kind": "step", "function_name": "step_power_on_ap", "description": "The connected AP is powered off/on：The AP power on", "category": "wifi", "tags": ["kind:step", "domain:wifi"], "params": {"ap_id": {"name": "ap_id", "type": "str", "required": false, "default": "AP1", "description": "AP标识"}}, "pre_conditions": [{"id": "step_power_off_ap", "type": "step", "reason": "前置步骤必须先完成"}], "post_conditions": []}, {"kind": "check", "function_name": "check_wifi_disconnected", "description": "验证The connected AP is powered off/on：After step 2，platform disconnect with the AP", "category": "wifi", "tags": ["kind:check", "domain:wifi"], "params": {}, "pre_conditions": [{"id": "step_power_on_ap", "type": "step", "reason": "需先完成测试步骤"}], "post_conditions": []}, {"kind": "check", "function_name": "check_wifi_auto_reconnected", "description": "验证The connected AP is powered off/on：After step 3，platform auto connect with the AP", "category": "wifi", "tags": ["kind:check", "domain:wifi"], "params": {"expected_ssid": {"name": "expected_ssid", "type": "str", "required": false, "default": null, "description": "预期自动重连的SSID"}}, "pre_conditions": [{"id": "step_power_on_ap", "type": "step", "reason": "需先完成测试步骤"}], "post_conditions": []}]
A22: Wifi_Func_016 | B22: Connect AP | C22: AP2 fail, back to AP1 | D22: Multiple APs | E22: connect another AP with wrong password | F22: connection fail. It will automatically switch to the AP1 connection | G22: P1 | H22: N/A | J22: weidong.feng | M22: Yes | O22: Summary（概要） 在Connect AP场景下执行「AP2 fail, back to AP1」，验证：connection fail. It will automatically switch to t Preconditions（前置条件/环境准备） 1. 平台已正常启动并进入系统 2. WiFi 模块已初始化 3. Multiple APs Steps（操作步骤） Step 1：connect another AP with wrong password 目的：完成「AP2 fail, back to AP1」测试操作 对应函数：step_connect_wifi(...) Checks（检查点） Check 1：connection fail. It will automatically switch to the AP1 connection 检查内容：connection fail. It will automatically switch to the AP1 connection 对应函数：check_wifi_connected(...) | P22: [{"kind": "step", "function_name": "step_connect_wifi", "description": "AP2 fail, back to AP1：connect another AP with wrong password", "category": "wifi", "tags": ["kind:step", "domain:wifi"], "params": {"ssid": {"name": "ssid", "type": "str", "required": true, "default": null, "description": "目标AP的SSID"}, "password": {"name": "password", "type": "str", "required": false, "default": null, "description": "WiFi密码，开放网络可为空"}, "auth_type": {"name": "auth_type", "type": "str", "required": false, "default": null, "description": "认证类型如 WPA2/WPA3/Open/WEP"}}, "pre_conditions": [], "post_conditions": []}, {"kind": "check", "function_name": "check_wifi_connected", "description": "验证AP2 fail, back to AP1：connection fail. It will automatically switch to the AP1 con", "category": "wifi", "tags": ["kind:check", "domain:wifi"], "params": {"expected_ssid": {"name": "expected_ssid", "type": "str", "required": false, "default": null, "description": "预期已连接的SSID"}}, "pre_conditions": [{"id": "step_connect_wifi", "type": "step", "reason": "需先完成测试步骤"}], "post_conditions": []}]
A23: Wifi_Func_017 | B23: Connect AP | C23: AP2 successfull | D23: Multiple APs | E23: entering the correct password | F23: AP2 connects successfully and disconnects from AP1 | G23: P1 | H23: N/A | J23: weidong.feng | M23: Yes | O23: Summary（概要） 在Connect AP场景下执行「AP2 successfull」，验证：AP2 connects successfully and disconnects from AP1 Preconditions（前置条件/环境准备） 1. 平台已正常启动并进入系统 2. WiFi 模块已初始化 3. Multiple APs Steps（操作步骤） Step 1：entering the correct password 目的：完成「AP2 successfull」测试操作 对应函数：step_connect_wifi(...) Checks（检查点） Check 1：AP2 connects successfully and disconnects from AP1 检查内容：AP2 connects successfully and disconnects from AP1 对应函数：check_wifi_connected(...) | P23: [{"kind": "step", "function_name": "step_connect_wifi", "description": "AP2 successfull：entering the correct password", "category": "wifi", "tags": ["kind:step", "domain:wifi"], "params": {"ssid": {"name": "ssid", "type": "str", "required": true, "default": null, "description": "目标AP的SSID"}, "password": {"name": "password", "type": "str", "required": false, "default": null, "description": "WiFi密码，开放网络可为空"}, "auth_type": {"name": "auth_type", "type": "str", "required": false, "default": null, "description": "认证类型如 WPA2/WPA3/Open/WEP"}}, "pre_conditions": [], "post_conditions": []}, {"kind": "check", "function_name": "check_wifi_connected", "description": "验证AP2 successfull：AP2 connects successfully and disconnects from AP1", "category": "wifi", "tags": ["kind:check", "domain:wifi"], "params": {"expected_ssid": {"name": "expected_ssid", "type": "str", "required": false, "default": null, "description": "预期已连接的SSID"}}, "pre_conditions": [{"id": "step_connect_wifi", "type": "step", "reason": "需先完成测试步骤"}], "post_conditions": []}]
A24: Wifi_Func_018 | B24: Connect AP | C24: Connected AP2 power off | D24: Multiple APs | E24: The currently connected AP2 is powered off | F24: 1.The platform will disconnect from AP2 and automatically connect to AP1 with saved password. 2.If the platform saves the passwords of multiple APs, select an AP with the strongest signal strength to connect automatically | G24: P1 | H24: N/A | J24: weidong.feng | K24: Yes | L24: Yes | M24: Yes | O24: Summary（概要） 在Connect AP场景下执行「Connected AP2 power off」，验证：The platform will disconnect from AP2 and automati；If the platform saves th Preconditions（前置条件/环境准备） 1. 平台已正常启动并进入系统 2. WiFi 模块已初始化 3. Multiple APs Steps（操作步骤） Step 1：The currently connected AP2 is powered off 目的：完成「Connected AP2 power off」测试操作 对应函数：step_connect_wifi(...) Checks（检查点） Check 1：The platform will disconnect from AP2 and automatically connect to AP1 with save 检查内容：The platform will disconnect from AP2 and automatically connect to AP1 with saved password. 对应函数：check_wifi_connected(...) Check 2：If the platform saves the passwords of multiple APs, select an AP with the stron 检查内容：If the platform saves the passwords of multiple APs, select an AP with the strongest signal strength to connect automatically 对应函数：check_wifi_connected(...) | P24: [{"kind": "step", "function_name": "step_connect_wifi", "description": "Connected AP2 power off：The currently connected AP2 is powered off", "category": "wifi", "tags": ["kind:step", "domain:wifi"], "params": {"ssid": {"name": "ssid", "type": "str", "required": true, "default": null, "description": "目标AP的SSID"}, "password": {"name": "password", "type": "str", "required": false, "default": null, "description": "WiFi密码，开放网络可为空"}, "auth_type": {"name": "auth_type", "type": "str", "required": false, "default": null, "description": "认证类型如 WPA2/WPA3/Open/WEP"}}, "pre_conditions": [], "post_conditions": []}, {"kind": "check", "function_name": "check_wifi_connected", "description": "验证Connected AP2 power off：The platform will disconnect from AP2 and automatically conn", "category": "wifi", "tags": ["kind:check", "domain:wifi"], "params": {"expected_ssid": {"name": "expected_ssid", "type": "str", "required": false, "default": null, "description": "预期已连接的SSID"}}, "pre_conditions": [{"id": "step_connect_wifi", "type": "step", "reason": "需先完成测试步骤"}], "post_conditions": []}]
A25: Wifi_Func_019 | B25: Connect AP | C25: AP2 power on | D25: Multiple APs | E25: AP2 is powered on again | F25: In the AP LIST interface, AP2 will automatically update the current status, and the help text becomes "saved" | G25: P1 | H25: N/A | J25: weidong.feng | M25: Yes | O25: Summary（概要） 在Connect AP场景下执行「AP2 power on」，验证：In the AP LIST interface, AP2 will automatically u Preconditions（前置条件/环境准备） 1. 平台已正常启动并进入系统 2. WiFi 模块已初始化 3. Multiple APs Steps（操作步骤） Step 1：AP2 is powered on again 目的：完成「AP2 power on」测试操作 对应函数：step_power_on_ap(...) Checks（检查点） Check 1：In the AP LIST interface, AP2 will automatically update the current status, and 检查内容：In the AP LIST interface, AP2 will automatically update the current status, and the help text becomes "saved" 对应函数：check_ap_list_display(...) | P25: [{"kind": "step", "function_name": "step_power_on_ap", "description": "AP2 power on：AP2 is powered on again", "category": "wifi", "tags": ["kind:step", "domain:wifi"], "params": {"ap_id": {"name": "ap_id", "type": "str", "required": false, "default": "AP1", "description": "AP标识"}}, "pre_conditions": [], "post_conditions": []}, {"kind": "check", "function_name": "check_ap_list_display", "description": "验证AP2 power on：In the AP LIST interface, AP2 will automatically update the ", "category": "wifi", "tags": ["kind:check", "domain:wifi"], "params": {}, "pre_conditions": [{"id": "step_power_on_ap", "type": "step", "reason": "需先完成测试步骤"}], "post_conditions": []}]
A26: Wifi_Func_020 | B26: Connect AP | C26: Saved status connect | D26: Multiple APs | E26: Select AP2 again on the AP LIST interface,click "Connect" option | F26: Connect AP2 successful | G26: P1 | H26: N/A | J26: weidong.feng | M26: Yes | O26: Summary（概要） 在Connect AP场景下执行「Saved status connect」，验证：Connect AP2 successful Preconditions（前置条件/环境准备） 1. 平台已正常启动并进入系统 2. WiFi 模块已初始化 3. Multiple APs Steps（操作步骤） Step 1：Select AP2 again on the AP LIST interface,click "Connect" option 目的：完成「Saved status connect」测试操作 对应函数：step_connect_wifi(...) Checks（检查点） Check 1：Connect AP2 successful 检查内容：Connect AP2 successful 对应函数：check_wifi_connected(...) | P26: [{"kind": "step", "function_name": "step_connect_wifi", "description": "Saved status connect：Select AP2 again on the AP LIST interface,click \"Connect\" op", "category": "wifi", "tags": ["kind:step", "domain:wifi"], "params": {"ssid": {"name": "ssid", "type": "str", "required": true, "default": null, "description": "目标AP的SSID"}, "password": {"name": "password", "type": "str", "required": false, "default": null, "description": "WiFi密码，开放网络可为空"}, "auth_type": {"name": "auth_type", "type": "str", "required": false, "default": null, "description": "认证类型如 WPA2/WPA3/Open/WEP"}}, "pre_conditions": [], "post_conditions": []}, {"kind": "check", "function_name": "check_wifi_connected", "description": "验证Saved status connect：Connect AP2 successful", "category": "wifi", "tags": ["kind:check", "domain:wifi"], "params": {"expected_ssid": {"name": "expected_ssid", "type": "str", "required": false, "default": null, "description": "预期已连接的SSID"}}, "pre_conditions": [{"id": "step_connect_wifi", "type": "step", "reason": "需先完成测试步骤"}], "post_conditions": []}]
A27: Wifi_Func_021 | B27: Connect AP | C27: Restart with wifi off | E27: Reboot the platform when the platform wifi switch is off | F27: After restart ，wifi switch keep closing status | G27: P1 | H27: N/A | J27: weidong.feng | M27: Yes | O27: Summary（概要） 在Connect AP场景下执行「Restart with wifi off」，验证：After restart ，wifi switch keep closing status Preconditions（前置条件/环境准备） 1. 平台已正常启动并进入系统 2. WiFi 模块已初始化 Steps（操作步骤） Step 1：Reboot the platform when the platform wifi switch is off 目的：完成「Restart with wifi off」测试操作 对应函数：step_toggle_wifi(...) Checks（检查点） Check 1：After restart ，wifi switch keep closing status 检查内容：After restart ，wifi switch keep closing status 对应函数：check_after_restart_wifi_switch_k(...) | P27: [{"kind": "step", "function_name": "step_toggle_wifi", "description": "Restart with wifi off：Reboot the platform when the platform wifi switch is off", "category": "wifi", "tags": ["kind:step", "domain:wifi"], "params": {"enabled": {"name": "enabled", "type": "bool", "required": true, "default": false, "description": "False=关闭WiFi"}}, "pre_conditions": [], "post_conditions": []}, {"kind": "check", "function_name": "check_after_restart_wifi_switch_k", "description": "验证Restart with wifi off：After restart ，wifi switch keep closing status", "category": "wifi", "tags": ["kind:check", "domain:wifi"], "params": {}, "pre_conditions": [{"id": "step_toggle_wifi", "type": "step", "reason": "需先完成测试步骤"}], "post_conditions": []}]
A28: Wifi_Func_022 | B28: Connect AP | C28: Restart wifi ap connected | E28: Reboot the platform when the platform connect an AP | F28: After restart ，wifi keep connectting status and search Internet normal | G28: P1 | H28: N/A | J28: weidong.feng | M28: Yes | O28: Summary（概要） 在Connect AP场景下执行「Restart wifi ap connected」，验证：After restart ，wifi keep connectting status and se Preconditions（前置条件/环境准备） 1. 平台已正常启动并进入系统 2. WiFi 模块已初始化 Steps（操作步骤） Step 1：Reboot the platform when the platform connect an AP 目的：完成「Restart wifi ap connected」测试操作 对应函数：step_connect_wifi(...) Checks（检查点） Check 1：After restart ，wifi keep connectting status and search Internet normal 检查内容：After restart ，wifi keep connectting status and search Internet normal 对应函数：check_wifi_state(...) | P28: [{"kind": "step", "function_name": "step_connect_wifi", "description": "Restart wifi ap connected：Reboot the platform when the platform connect an AP", "category": "wifi", "tags": ["kind:step", "domain:wifi"], "params": {"ssid": {"name": "ssid", "type": "str", "required": true, "default": null, "description": "目标AP的SSID"}, "password": {"name": "password", "type": "str", "required": false, "default": null, "description": "WiFi密码，开放网络可为空"}, "auth_type": {"name": "auth_type", "type": "str", "required": false, "default": null, "description": "认证类型如 WPA2/WPA3/Open/WEP"}}, "pre_conditions": [], "post_conditions": []}, {"kind": "check", "function_name": "check_wifi_state", "description": "验证Restart wifi ap connected：After restart ，wifi keep connectting status and search Inter", "category": "wifi", "tags": ["kind:check", "domain:wifi"], "params": {"expected": {"name": "expected", "type": "bool", "required": true, "default": true, "description": "True=WiFi应开启"}}, "pre_conditions": [{"id": "step_connect_wifi", "type": "step", "reason": "需先完成测试步骤"}], "post_conditions": []}]
A29: Wifi_Func_023 | B29: Connect AP | C29: Standby wake up reconnect | E29: wakeup the platform from standby when the platform connect an AP | F29: After waking up ，wifi keep connectting status and search Internet normal | G29: P1 | H29: N/A | J29: weidong.feng | M29: Yes | O29: Summary（概要） 在Connect AP场景下执行「Standby wake up reconnect」，验证：After waking up ，wifi keep connectting status and Preconditions（前置条件/环境准备） 1. 平台已正常启动并进入系统 2. WiFi 模块已初始化 Steps（操作步骤） Step 1：wakeup the platform from standby when the platform connect an AP 目的：完成「Standby wake up reconnect」测试操作 对应函数：step_connect_wifi(...) Checks（检查点） Check 1：After waking up ，wifi keep connectting status and search Internet normal 检查内容：After waking up ，wifi keep connectting status and search Internet normal 对应函数：check_wifi_state(...) | P29: [{"kind": "step", "function_name": "step_connect_wifi", "description": "Standby wake up reconnect：wakeup the platform from standby when the platform connect a", "category": "wifi", "tags": ["kind:step", "domain:wifi"], "params": {"ssid": {"name": "ssid", "type": "str", "required": true, "default": null, "description": "目标AP的SSID"}, "password": {"name": "password", "type": "str", "required": false, "default": null, "description": "WiFi密码，开放网络可为空"}, "auth_type": {"name": "auth_type", "type": "str", "required": false, "default": null, "description": "认证类型如 WPA2/WPA3/Open/WEP"}}, "pre_conditions": [], "post_conditions": []}, {"kind": "check", "function_name": "check_wifi_state", "description": "验证Standby wake up reconnect：After waking up ，wifi keep connectting status and search Int", "category": "wifi", "tags": ["kind:check", "domain:wifi"], "params": {"expected": {"name": "expected", "type": "bool", "required": true, "default": true, "description": "True=WiFi应开启"}}, "pre_conditions": [{"id": "step_connect_wifi", "type": "step", "reason": "需先完成测试步骤"}], "post_conditions": []}]
A30: Wifi_Func_024 | B30: Connect AP | C30: Switch ap | E30: Switching connecting between AP1 and AP2 | F30: Switch connecting successful | G30: P1 | H30: N/A | J30: weidong.feng | M30: Yes | O30: Summary（概要） 在Connect AP场景下执行「Switch ap」，验证：Switch connecting successful Preconditions（前置条件/环境准备） 1. 平台已正常启动并进入系统 2. WiFi 模块已初始化 Steps（操作步骤） Step 1：Switching connecting between AP1 and AP2 目的：完成「Switch ap」测试操作 对应函数：step_connect_wifi(...) Checks（检查点） Check 1：Switch connecting successful 检查内容：Switch connecting successful 对应函数：check_wifi_connected(...) | P30: [{"kind": "step", "function_name": "step_connect_wifi", "description": "Switch ap：Switching connecting between AP1 and AP2", "category": "wifi", "tags": ["kind:step", "domain:wifi"], "params": {"ssid": {"name": "ssid", "type": "str", "required": true, "default": null, "description": "目标AP的SSID"}, "password": {"name": "password", "type": "str", "required": false, "default": null, "description": "WiFi密码，开放网络可为空"}, "auth_type": {"name": "auth_type", "type": "str", "required": false, "default": null, "description": "认证类型如 WPA2/WPA3/Open/WEP"}}, "pre_conditions": [], "post_conditions": []}, {"kind": "check", "function_name": "check_wifi_connected", "description": "验证Switch ap：Switch connecting successful", "category": "wifi", "tags": ["kind:check", "domain:wifi"], "params": {"expected_ssid": {"name": "expected_ssid", "type": "str", "required": false, "default": null, "description": "预期已连接的SSID"}}, "pre_conditions": [{"id": "step_connect_wifi", "type": "step", "reason": "需先完成测试步骤"}], "post_conditions": []}]
